---
title: 错误处理方案
categories: JavaScript
tags: JavaScript
toc: true # 是否启用内容索引
sidebar: true
---

### 错误处理方案

- 开发中我们会封装一些工具函数，封装之后给别人使用：
  - 在其他人使用的过程中，可能会传递一些参数；
  - 对于函数来说，需要对这些参数进行验证，否则可能得到的是我们不想要的结果；
- 很多时候我们可能验证到不是希望得到的参数时，就会直接return：
  - 但是return存在很大的弊端：调用者不知道是因为函数内部没有正常执行，还是执行结果就是一个undefined；
  - 事实上，正确的做法应该是如果没有通过某些验证，那么应该让外界知道函数内部报错了；
- 如何可以让一个函数告知外界自己内部出现了错误呢？
  - 通过throw关键字，抛出一个异常；
- throw语句：
  - throw语句用于抛出一个用户自定义的异常；
  - 当遇到throw语句时，当前的函数执行会被停止（throw后面的语句不会执行）；
- 如果我们执行代码，就会报错，拿到错误信息的时候我们可以及时的去修正代码；

```javascript
/**
 * 如果我们有一个函数，在调用这个函数时，如果出现了错误，那么我们应该是去修复这个错误
 */
function sum(num1, num2) {
  if (typeof num1 !== "number" || typeof num2 !== "number") {
    // return undefined
    // return
    throw "parameters is error type~"
  }
  return num1 + num2;
}
console.log(sum({name: 'xy'}, true))
console.log("后续代码")
```

```javascript
class XYError {
  constructor(errorCode, errorMessage){
    this.errorCode = errorCode;
    this.errorMessage = errorMessage
  }
}
function foo(type) {
  console.log("foo函数开始执行")
  if (type  === 0) {
  // 1.抛出一个字符串类型（基本数据类型）
  throw "type不能为0"
  // 2.比较常见的是抛出一个对象类型
  throw { errorCode: -1001, errorMessage: 'type不能为0' } 
  // 3.创建类并且创建这个类对应的对象
  throw new XYError(-1001, 'type不能为0')
  }
  console.log("foo函数结束执行")
}
foo(0)
```

### Error类型

- 事实上，JavaScript已经给我们提供了一个Error类，我们可以直接创建这个类的对象：

  ```javascript
  function foo() {
    throw new Error("err message");
  }
  ```

- Error包含三个属性：

  - messsage：创建Error对象时传入的message；
  - name：Error的名称，通常和类的名称一致；
  - stack：整个Error的错误信息，包括函数的调用栈，当我们直接打印Error对象时，打印的就是stack；

- Error有一些自己的子类：

  - RangeError：下标值越界时使用的错误类型；
  - SyntaxError：解析语法错误时使用的错误类型；
  - TypeError：出现类型错误时，使用的错误类型；

```javascript
function foo(type) {
  // 4.提供了一个Error
  throw new Error("type不能为0")

  const err = new Error("type不能为0");
  console.log(err.name);
  console.log(err.message)
  throw err;

  // 5.Error的子类
  throw new TypeError("type不能为0")

  // 强调：若果函数中已经抛出了异常，那么后续代码都不会再继续执行
  console.log("foo函数的后续代码")
}
```

### 异常的捕获

- 但是很多情况下当出现异常时，我们并不希望程序直接推出，而是希望可以正确的处理异常：

  - 这个时候我们就可以使用try catch

  ```javascript
  function foo(type) {
    if (type === 0) {
      throw new Error("foo error message");
    }
  }
  function bar() {
    // 但是很多情况下当出现异常时，我们并不希望程序直接推出，而是希望可以正确的处理异常：
    try {
      foo(0);
      console.log("bar函数后续的继续执行")
    } catch (err) {
      // 在ES10中 可以把catch的参数省略，只需要知道执行的try中的代码有错误即可
      console.log(err)
      console.log("err后续代码")
    }
  }
  ```

- 在ES10（ES2019）中，catch后面绑定的error可以省略。

- 当然，如果有一些必须要执行的代码，我们可以使用finally来执行：

  - finally表示最终一定会被执行的代码结构；
  - 注意：如果try和finally中都有返回值，那么会使用finally当中的返回值；

  ```javascript
  finally {
    // 跟java中很像，也例如promise中的finally方法
    // 作用： 服务端 做最后的操作，比如关闭数据库连接，close();
    console.log("finally代码执行")
  }
  ```

- try catch的捕获两种处理方案

  ```javascript
  /**
   * 两种处理方法：
   * 1.第一种是不处理，那么异常会进一步的抛出，知道最顶层的调用
   * 2.如果在最顶层也没有对这个异常进行处理，那么我们的程序就会终止执行，并且报错
   */
  ```

  